Workbook

Sheet Calculos
A1: CALCULO DE REQUISITOS ENERGÉTICOS DIARIOS | E1: CALCULO DE TEMPORALIZACIÓN DE OBJETIVOS PARA PERDIDA DE GRASA
A2: Sexo | B2: Hombre | C2: =IF(B2="Hombre",9,8) -> 9 | E2: Peso Actual | H2: 70
A3: Edad | B3: Menos de 40 años | C3: =IF(B3="Menos de 40 años",8,6) -> 8 | E3: Peso Objetivo | H3: 68
A4: Peso | B4: 68 | E4: Semanas Previstas para llegar al Peso Objetivo | H4: =QUOTIENT(H2-H3,0.5) -> 4 | K4: Meses
A5: Actividad | B5: Activo | C5: =IF(B5="Activo",9,6) -> 9 | K5: =H4/4.3 -> 0.93023256
A6: Tendencia Corporal | B6: Suelo Engordar Facil | C6: =IF(B6="Suelo Adelgazar Facil",6,4) -> 4 | E6: CALCULO DE TEMPORALIZACIÓN DE OBJETIVOS PARA AUMENTO DE MUSCULO
C7: =SUM(C2:C6) -> 30
A8: Energia Estimada para Mantenimiento | B8: =B4*C7 -> 2040 | E8: Peso Actual
A9: Hipertrofia o Aumento de Peso | B9: =B8+500 -> 2540 | E9: Peso Objetivo | K9: Meses
A10: Definicion o Pérdida de Peso | B10: =B8-500 -> 1540 | E10: Semanas Previstas para llegar al Peso Objetivo | H10: =QUOTIENT(H9-H8,0.1) -> 0 | K10: =H9/4.3 -> 0
A79: Hombre | B79: Mujer
A80: Menos de 40 años | B80: Mas de 40 años
A81: Sedentario | B81: Activo
A82: Suelo Engordar Facil | B82: Suelo Adelgazar Facil

Sheet Resultados
A1: Agua (g) | B1: Calorias (Kcal) | C1: Proteínas (g) | D1: Grasas (g) | E1: Hidratos de Carbono (g) | F1: Sodio: Na | G1: Potasio: K | H1: Fósforo: P | I1: Calcio: Ca | J1: Magnesio
F2: (mg) | G2: (mg) | H2: (mg) | I2: (mg) | J2: (mg)
A3: =Càlculs!C164 -> 1168.73 | B3: =Càlculs!D164 -> 1967.61 | C3: =Càlculs!E164 -> 165.775 | D3: =Càlculs!F164 -> 47.14 | E3: =Càlculs!G164 -> 221.135 | F3: =Càlculs!H164 -> 965.475 | G3: =Càlculs!I164 -> 4067.1 | H3: =Càlculs!J164 -> 1575.3 | I3: =Càlculs!K164 -> 357.9 | J3: =Càlculs!U164 -> 461
A6: Precio | B6: Colesterol | C6: Hierro: Fe | D6: Vitamina C | E6: Tiamina | F6: Riboflavina | G6: Niacina | H6: Vitamina D | I6: Retinol-A | J6: Ac. Fólico
A7: (euros) | B7: (mg) | C7: (mg) | D7: (mg) | E7: (mg) | F7: (mg) | G7: (mg) | H7: (microg.) | I7: (microg.) | J7: (mg)
A8: =Càlculs!S164 -> 6.32 | B8: =Càlculs!T164 -> 565.5 | C8: =Càlculs!L164 -> 18.625 | D8: =Càlculs!M164 -> 122.1 | E8: =Càlculs!N164 -> 1.471 | F8: =Càlculs!O164 -> 2.534 | G8: =Càlculs!P164 -> 27.805 | H8: =Càlculs!Q164 -> 1414 | I8: =Càlculs!R164 -> 180 | J8: =Càlculs!L169 -> 0
A12: % Kcal Proteínas | B12: =E12/E15*100 -> 33.627466 | D12: Kcal Prot. | E12: =Càlculs!G169 -> 663.1
A13: % Kcal Grasa | B13: =E13/E15*100 -> 21.51529 | D13: Kcal Grasa | E13: =Càlculs!G170 -> 424.26
A14: % Kcal Glúcidos | B14: =E14/E15*100 -> 44.857244 | D14: Kcal Glúcidos | E14: =Càlculs!G171 -> 884.54
A15: Relación Ca/P | B15: =Càlculs!C172 -> 0.22719482 | D15: Total Kcal | E15: =Càlculs!G172 -> 1971.9
A17: % Glúcidos simples | B17: =Càlculs!C174 -> 0 | D17: % Prot. Anim. | E17: =Càlculs!G174 -> 79.96079
B19: HORA | C19: KCAL: | D19: =B3 -> 1967.61 | E19: PROT: | F19: =C3 -> 165.775 | G19: HC: | H19: =E3 -> 221.135 | I19: GRASA: | J19: =D3 -> 47.14
B21: 1era | C21: tortitas avena (1 huevos + 150 ml claras + 50 g harina de arroz o harina avena + 75g frutos rojos)
B23: 2a | C23: 50 arroz + 150g pollo + 100g verduras +20g aguacate
B25: 3a | C25: tortitas avena (1 huevos + 150 ml claras + 50 g harina de arroz o harina avena + 75g frutos rojos) o 35g proteina + 30g tortitas arroz + platano
B27: 4ª | C27: 200g patata asada + 150 ternera + 100g verduras + 15g cacao
B29: 5a
B31: pre cama
B33: Post entrenamiento | C33: 35g proteina + 20g arroz + 1 platano

Sheet Carnes y Pescados
C1: Aigua | D1: Calories | E1: Proteïna | F1: Lípids totals | G1: Glúcids totals | H1: Sodi: Na | I1: Potassi: K | J1: Fósfor: P | K1: Calci: Ca | L1: Ferro: Fe | M1: Vitamina C | N1: Tiamina | O1: Riboflavina | P1: Niacina | Q1: Carotens | R1: Retinol | S1: Preu | T1: Colesterol | U1: Magnesi | V1: Fibra | W1: Zinc | X1: Vitamina E | Y1: Vitamina K | Z1: Acido Fólico | AA1: Leucina
C2: (g) | D2: (Kcal) | E2: (g) | F2: (g) | G2: (g) | H2: (mg) | I2: (mg) | J2: (mg) | K2: (mg) | L2: (mg) | M2: (mg) | N2: (mg) | O2: (mg) | P2: (mg) | Q2: (microg.) | R2: (microg.) | S2: (euros/100gr) | T2: (mg) | U2: (mg) | V2: (mg) | W2: (mg) | X2: (mg) | Y2: (mg) | Z2: (mg) | AA2: (mg)
A3: Cantidad | B3: Carnes
B4: Caballo | C4: 76 | D4: 108 | E4: 20.6 | F4: 2.7 | G4: 0.4 | H4: 44 | I4: 377 | J4: 200 | K4: 9.2 | L4: 4.8 | M4: 0 | N4: 0.11 | O4: 0.15 | P4: 6.6 | Q4: 0 | R4: 21 | S4: 1.1 | T4: 54 | U4: 26
A5: 150 | B5: Ternera (Bistec) | C5: 68.2 | D5: 175 | E5: 19 | F5: 11 | G5: 0 | H5: 70 | I5: 360 | J5: 203 | K5: 8 | L5: 2.9 | M5: 0 | N5: 0.08 | O5: 0.21 | P5: 4.7 | Q5: 0 | R5: 0 | S5: 0.89 | T5: 74 | U5: 20
B6: Cordero | C6: 64 | D6: 240 | E6: 17 | F6: 19 | G6: 0 | H6: 70 | I6: 300 | J6: 170 | K6: 9 | L6: 2.7 | M6: 0 | N6: 0.13 | O6: 0.2 | P6: 5 | Q6: 0 | R6: 0 | S6: 1.395 | T6: 77 | U6: 22
B7: Cerdo (Lomo) | C7: 58.4 | D7: 304 | E7: 16.3 | F7: 26.6 | G7: 0 | H7: 75 | I7: 290 | J7: 190 | K7: 9 | L7: 2 | M7: 0.2 | N7: 0.79 | O7: 0.2 | P7: 4.1 | Q7: 0 | R7: 0 | S7: 0.549 | T7: 64 | U7: 20
B8: Conejo | C8: 68 | D8: 160 | E8: 22 | F8: 8 | G8: 0 | H8: 47 | I8: 360 | J8: 220 | K8: 20 | L8: 1.5 | M8: 0 | N8: 0.07 | O8: 0.12 | P8: 8.7 | Q8: 0 | R8: 0 | S8: 0.72 | T8: 58 | U8: 25
A9: 150 | B9: Pollo, Pechuga sin Piel | C9: 74.6 | D9: 121 | E9: 20.5 | F9: 4.3 | G9: 0 | H9: 78 | I9: 300 | J9: 200 | K9: 12 | L9: 1 | M9: 4 | N9: 0.08 | O9: 0.17 | P9: 8 | Q9: 0 | R9: 0 | S9: 0.499 | T9: 63 | U9: 23
B10: Pavo, Fiambre | C10: 77.5 | D10: 84 | E10: 17.9 | F10: 0.8 | G10: 3 | H10: 1180 | I10: 262 | J10: 276 | K10: 15 | L10: 2 | M10: 0 | N10: 0.3 | O10: 0.4 | P10: 5.5 | Q10: 0 | R10: 7 | S10: 0.9 | T10: 40 | U10: 19
B11: Ternera (Higado) | C11: 70.5 | D11: 134 | E11: 20 | F11: 5 | G11: 4 | H11: 125 | I11: 320 | J11: 305 | K11: 9 | L11: 7 | M11: 25 | N11: 0.3 | O11: 3 | P11: 15 | Q11: 12.5 | R11: 12500 | S11: 0.65 | T11: 335 | U11: 20
B12: Jamón Cocido | C12: 68.7 | D12: 170 | E12: 20.7 | F12: 9.3 | G12: 0.7 | H12: 910 | I12: 300 | J12: 180 | K12: 10 | L12: 2.3 | M12: 0 | N12: 0.5 | O12: 0.2 | P12: 5 | Q12: 0 | R12: 0 | S12: 0.179 | T12: 48 | U12: 21
B13: Jamón Curado | C13: 63 | D13: 210 | E13: 22.5 | F13: 12.8 | G13: 0.4 | H13: 1200 | I13: 230 | J13: 190 | K13: 13 | L13: 2.3 | M13: 0 | N13: 0.57 | O13: 0.25 | P13: 5 | Q13: 0 | R13: 0 | S13: 2.59 | T13: 68 | U13: 22
B14: Embutidos Curados (Chorizo, Salchichón) | C14: 48.8 | D14: 356 | E14: 21.2 | F14: 29.3 | G14: 1.9 | H14: 2100 | I14: 160 | J14: 200 | K14: 18 | L14: 2 | M14: 0 | N14: 0.33 | O14: 0.15 | P14: 5 | Q14: 0 | R14: 0 | S14: 1.85 | T14: 75 | U14: 14
B15: Embutidos Cocidos (Butifarra, Salchichas) | C15: 49.3 | D15: 330 | E15: 15.2 | F15: 29.3 | G15: 1.3 | H15: 660 | I15: 185 | J15: 130 | K15: 14 | L15: 2 | M15: 0 | N15: 0.11 | O15: 0.15 | P15: 5 | Q15: 0 | R15: 0 | S15: 0.85 | T15: 75 | U15: 15
B16: Pavo, Pechuga sin Piel | C16: 74.4 | D16: 100 | E16: 21.9 | F16: 1.4 | G16: 0 | H16: 63 | I16: 353 | J16: 210 | K16: 8 | L16: 0.7 | M16: 0 | N16: 0.07 | O16: 0.12 | P16: 7.9 | Q16: 0 | R16: 0 | S16: 0.65 | T16: 65 | U16: 32
B17: Hamburguesa de Ternera | C17: 51 | D17: 295 | E17: 23 | F17: 12 | G17: 1 | H17: 450 | I17: 310 | S17: 0.7 | T17: 75 | U17: 8
B18: Hamburguesa de Pollo | C18: 68 | D18: 152 | E18: 18 | F18: 8 | G18: 0 | H18: 475 | I18: 235 | S18: 0.7 | T18: 75 | U18: 8
C20: Aigua | D20: Calories | E20: Proteïna | F20: Lípids totals | G20: Glúcids totals | H20: Sodi: Na | I20: Potassi: K | J20: Fósfor: P | K20: Calci: Ca | L20: Ferro: Fe | M20: Vitamina C | N20: Tiamina | O20: Riboflavina | P20: Niacina | Q20: Carotens | R20: Retinol | S20: Preu | T20: Colesterol | U20: Magnesi
C21: (g) | D21: (Kcal) | E21: (g) | F21: (g) | G21: (g) | H21: (mg) | I21: (mg) | J21: (mg) | K21: (mg) | L21: (mg) | M21: (mg) | N21: (mg) | O21: (mg) | P21: (mg) | Q21: (microg.) | R21: (microg.) | S21: (euros/100gr) | T21: (mg) | U21: (mg)
A22: Cantidad | B22: Pescados
B23: Pescado Blanco (Merluza, Mero, Lenguado) | C23: 80 | D23: 89.6 | E23: 17.9 | F23: 2 | G23: 0 | H23: 100 | I23: 275 | J23: 190 | K23: 40 | L23: 1 | M23: 0 | N23: 0.09 | O23: 0.2 | P23: 5.5 | Q23: 0.01 | R23: 0.01 | S23: 0.695 | T23: 50 | U23: 30
B24: Pescado azul (Sardina, Caballa) | C24: 70 | D24: 170 | E24: 20 | F24: 10 | G24: 0 | H24: 78 | I24: 336 | J24: 300 | K24: 50 | L24: 1.2 | M24: 0 | N24: 0.05 | O24: 0.33 | P24: 6.4 | Q24: 0.01 | R24: 50 | S24: 0.799 | T24: 50 | U24: 33
B25: Crustaceos | C25: 78 | D25: 90 | E25: 19.2 | F25: 1.3 | G25: 0 | H25: 366 | I25: 300 | J25: 250 | K25: 100 | L25: 1.5 | M25: 0 | N25: 0.01 | O25: 0.03 | P25: 2 | Q25: 0.01 | R25: 0.01 | S25: 1 | T25: 110 | U25: 29
B26: Moluscos | C26: 71.4 | D26: 118 | E26: 20.2 | F26: 2.8 | G26: 3.1 | H26: 290 | I26: 290 | J26: 290 | K26: 100 | L26: 7.3 | M26: 0 | N26: 0.1 | O26: 0.11 | P26: 1 | Q26: 0.01 | R26: 84 | S26: 0.695 | T26: 100 | U26: 32
B27: Atún, lata aceite de oliva (escurrido) | C27: 64 | D27: 180 | E27: 26.5 | F27: 8 | G27: 0 | H27: 396 | I27: 333 | J27: 267 | K27: 4 | L27: 0.65 | M27: 0 | N27: 0.02 | O27: 0.08 | P27: 11.7 | Q27: 5 | R27: 62 | S27: 1.2 | T27: 31 | U27: 30
B28: Sardina, lata aceite oliva | C28: 62.8 | D28: 221 | E28: 23.99 | F28: 13.9 | G28: 0 | H28: 465 | I28: 380 | J28: 494 | K28: 314 | L28: 2.9 | M28: 0 | N28: 0.03 | O28: 0.3 | P28: 8.1 | Q28: 5.5 | R28: 10 | S28: 0.8 | T28: 72 | U28: 49.3
B29: Atún, lata al natural (escurrido) | C29: 69 | D29: 108 | E29: 25 | F29: 1 | G29: 0 | H29: 368 | I29: 254 | J29: 176 | K29: 9 | L29: 1.3 | M29: 0 | N29: 0.02 | O29: 0.09 | P29: 12.8 | Q29: 0 | R29: 26 | S29: 1.2 | T29: 53 | U29: 28
B30: Panga | C30: 83.8 | D30: 80 | E30: 13.4 | F30: 1.2 | G30: 0 | H30: 110 | I30: 200 | J30: 107 | K30: 36.7 | L30: 0.21 | M30: 0 | N30: 0.04 | O30: 0.04 | P30: 0.35 | Q30: 0.01 | R30: 0.01 | S30: 0.44 | T30: 29.8 | U30: 17.6
B31: Salmón | C31: 69.6 | D31: 182 | E31: 18.4 | F31: 12 | G31: 0 | H31: 98 | I31: 310 | J31: 250 | K31: 27 | L31: 0.7 | M31: 0 | N31: 0.2 | O31: 0.15 | P31: 10.4 | Q31: 0.01 | R31: 50 | S31: 1.25 | T31: 50 | U31: 26

Sheet Huevos y Lacteos
C1: Aigua | D1: Calories | E1: Proteïna | F1: Lípids totals | G1: Glúcids totals | H1: Sodi: Na | I1: Potassi: K | J1: Fósfor: P | K1: Calci: Ca | L1: Ferro: Fe | M1: Vitamina C | N1: Tiamina | O1: Riboflavina | P1: Niacina | Q1: Carotens | R1: Retinol | S1: Preu | T1: Colesterol | U1: Magnesi
C2: (g) | D2: (Kcal) | E2: (g) | F2: ((g) | G2: (g) | H2: (mg) | I2: (mg) | J2: (mg) | K2: (mg) | L2: (mg) | M2: (mg) | N2: (mg) | O2: (mg) | P2: (mg) | Q2: (microg.) | R2: (microg.) | S2: (euros/100gr) | T2: (mg) | U2: (mg)
A3: Cantidad | B3: Huevos
A4: 90 | B4: Huevo Entero | C4: 75 | D4: 162 | E4: 12.7 | F4: 12.1 | G4: 0.7 | H4: 130 | I4: 130 | J4: 200 | K4: 56 | L4: 2.2 | M4: 0 | N4: 0.11 | O4: 0.32 | P4: 0.1 | Q4: 40 | R4: 200 | S4: 0.25 | T4: 400 | U4: 12
A5: 300 | B5: Huevo Clara | C5: 87.9 | D5: 46 | E5: 10.3 | F5: 0.1 | G5: 0.9 | H5: 150 | I5: 140 | J5: 18 | K5: 10 | L5: 0.1 | M5: 0 | N5: 0.01 | O5: 0.36 | P5: 0.1 | Q5: 0 | R5: 0 | S5: 0.34 | T5: 0 | U5: 10
B6: Huevo Yema | C6: 50 | D6: 361 | E6: 16 | F6: 32.8 | G6: 0.4 | H6: 55 | I6: 110 | J6: 535 | K6: 135 | L6: 6 | M6: 0 | N6: 0.3 | O6: 0.45 | P6: 0.06 | Q6: 124 | R6: 570 | S6: 0.3 | T6: 1100 | U6: 15
B7: Flan de huevo | C7: 70 | D7: 131 | E7: 4.8 | F7: 3.4 | G7: 20.4 | H7: 63 | I7: 122 | J7: 107 | K7: 91 | L7: 0.7 | M7: 0 | N7: 0.05 | O7: 0.17 | P7: 0.43 | Q7: 20 | R7: 92 | S7: 0.1 | T7: 100 | U7: 13
S8: 2.2 | T8: 0 | U8: 0
B9: Suplementos Deportivos | S9: 1.5 | T9: 0 | U9: 0
B10: Proteina de Suero (Concentrado) | C10: 10 | D10: 386 | E10: 76.7 | F10: 4.9 | G10: 8.3 | H10: 180 | S10: 2.2 | T10: 100
B11: Carbohidratos en Polvo | D11: 380 | E11: 0 | F11: 0 | G11: 95 | S11: 1.1
A12: 35 | B12: Proteina de Suero (Aislado ) | C12: 8 | D12: 369.6 | E12: 88.5 | F12: 1.8 | G12: 1.7 | H12: 304.5 | S12: 3.5
B13: Ganador de Peso Gainer (60HC/30Prot) | C13: 7 | D13: 381 | E13: 28 | F13: 1.4 | G13: 63 | H13: 0 | I13: 0 | J13: 0 | K13: 0 | L13: 3 | M13: 0 | N13: 0.35 | O13: 0.4 | P13: 4.5 | Q13: 0 | R13: 0 | S13: 2 | T13: 0 | U13: 3.62
C15: Aigua | D15: Calories | E15: Proteïna | F15: Lípids totals | G15: Glúcids totals | H15: Sodi: Na | I15: Potassi: K | J15: Fósfor: P | K15: Calci: Ca | L15: Ferro: Fe | M15: Vitamina C | N15: Tiamina | O15: Riboflavina | P15: Niacina | Q15: Carotens | R15: Retinol | S15: Preu | T15: Colesterol | U15: Magnesi
C16: (g) | D16: (Kcal) | E16: (g) | F16: ((g) | G16: (g) | H16: (mg) | I16: (mg) | J16: (mg) | K16: (mg) | L16: (mg) | M16: (mg) | N16: (mg) | O16: (mg) | P16: (mg) | Q16: (microg.) | R16: (microg.) | S16: (euros/100gr) | T16: (mg) | U16: (mg)
A17: Cantidad | B17: Leche y Derivados
B18: Leche de Vaca, entera | C18: 88 | D18: 65 | E18: 3.1 | F18: 3.8 | G18: 4.7 | H18: 45 | I18: 148 | J18: 86 | K18: 124 | L18: 0.1 | M18: 1 | N18: 0.04 | O18: 0.17 | P18: 0.18 | Q18: 18 | R18: 39 | S18: 0.08 | T18: 14 | U18: 11
B19: Leche vaca semidesnatada | C19: 89 | D19: 47 | E19: 3 | F19: 2 | G19: 5 | H19: 46 | I19: 166 | J19: 85 | K19: 120 | L19: 0.1 | M19: 1 | N19: 0.05 | O19: 0.18 | P19: 0.1 | Q19: 10 | R19: 18 | S19: 0.08 | T19: 7 | U19: 11
B20: Leche de Vaca, desnatada | C20: 91 | D20: 34 | E20: 3.2 | F20: 0.2 | G20: 4.8 | H20: 48 | I20: 160 | J20: 90 | K20: 115 | L20: 0.1 | M20: 1 | N20: 0.04 | O20: 0.17 | P20: 0.1 | Q20: 0 | R20: 0 | S20: 0.08 | T20: 2 | U20: 10
B21: Leche de Soja | C21: 88 | D21: 53 | E21: 3.2 | F21: 1.84 | G21: 5.76 | H21: 3 | I21: 191 | J21: 47 | K21: 3 | L21: 0.8 | M21: 0 | N21: 0.12 | O21: 0.42 | P21: 0.88 | Q21: 2 | R21: 2 | S21: 0.09 | T21: 0 | U21: 28
B22: Yogur | C22: 88 | D22: 61 | E22: 4 | F22: 3 | G22: 4.5 | H22: 65 | I22: 210 | J22: 110 | K22: 142 | L22: 0.2 | M22: 1 | N22: 0.04 | O22: 0.18 | P22: 0.15 | Q22: 16 | R22: 30 | S22: 0.18 | T22: 12 | U22: 16
B23: Yogur Griego | C23: 82.9 | D23: 118 | E23: 3.6 | F23: 10 | G23: 5.4 | H23: 40 | I23: 11 | J23: 87 | K23: 117 | L23: 0.09 | M23: 0 | N23: 0.04 | O23: 0.14 | P23: 0.15 | Q23: 16 | R23: 30 | S23: 0.2 | T23: 12 | U23: 11
B24: Queso Fresco | C24: 68 | D24: 175 | E24: 15 | F24: 11 | G24: 4 | H24: 137 | I24: 228 | J24: 205 | K24: 104 | L24: 0.3 | M24: 0.5 | N24: 0.03 | O24: 0.24 | P24: 0.6 | Q24: 110 | R24: 75 | S24: 0.45 | T24: 14 | U24: 12
B25: Queso Semi | C25: 41 | D25: 376 | E25: 29 | F25: 28.7 | G25: 0.5 | H25: 600 | I25: 120 | J25: 520 | K25: 800 | L25: 0.6 | M25: 0 | N25: 0.04 | O25: 0.3 | P25: 0.07 | Q25: 135 | R25: 215 | S25: 0.75 | T25: 70 | U25: 36
B26: Queso Curado | C26: 36 | D26: 416 | E26: 28 | F26: 33.5 | G26: 0.5 | H26: 900 | I26: 113 | J26: 700 | K26: 848 | L26: 0.8 | M26: 0 | N26: 0.04 | O26: 0.4 | P26: 0.1 | Q26: 200 | R26: 310 | S26: 0.98 | T26: 90 | U26: 46
B27: Queso para Fundir | C27: 53.2 | D27: 273 | E27: 16.7 | F27: 21.3 | G27: 3.8 | H27: 1320 | I27: 130 | J27: 800 | K27: 425 | L27: 0.9 | M27: 0 | N27: 0.06 | O27: 0.46 | P27: 1.1 | Q27: 222 | R27: 400 | S27: 0.85 | T27: 110 | U27: 30
B28: Yogur Liquido, desnatado | C28: 90 | D28: 40 | E28: 4.5 | F28: 0.4 | G28: 4.4 | H28: 50 | I28: 220 | J28: 125 | K28: 148 | L28: 0.1 | M28: 1 | N28: 0.04 | O28: 0.17 | P28: 0.13 | Q28: 0.04 | R28: 0 | S28: 0.18 | T28: 1 | U28: 17
B29: Helado Cremoso | C29: 62 | D29: 199 | E29: 2.8 | F29: 9.2 | G29: 26.2 | H29: 71 | I29: 180 | J29: 109 | K29: 135 | L29: 0.2 | M29: 0.4 | N29: 0.05 | O29: 0.22 | P29: 0.1 | Q29: 0.05 | R29: 50 | S29: 0.1 | T29: 28 | U29: 14
... B31: Queso Gouda Light (Bon Area) | C31: 54 | D31: 260 | E31: 29 | F31: 16 | G31: 0 | H31: 512 | I31: 121 | J31: 546 | K31: 700 | L31: 0.2 | M31: 0 | N31: 0 | O31: 0.3 | P31: 0.1 | Q31: 222 | R31: 400 | S31: 0.61 | T31: 114 | U31: 29

Sheet Cereales y Legumbres
C1: Aigua | D1: Calories | E1: Proteïna | F1: Lípids totals | G1: Glúcids totals | H1: Sodi: Na | I1: Potassi: K | J1: Fósfor: P | K1: Calci: Ca | L1: Ferro: Fe | M1: Vitamina C | N1: Tiamina | O1: Riboflavina | P1: Niacina | Q1: Carotens | R1: Retinol | S1: Preu | T1: Colesterol | U1: Magnesi
C2: (g) | D2: (Kcal) | E2: (g) | F2: ((g) | G2: (g) | H2: (mg) | I2: (mg) | J2: (mg) | K2: (mg) | L2: (mg) | M2: (mg) | N2: (mg) | O2: (mg) | P2: (mg) | Q2: (microg.) | R2: (microg.) | S2: (euros/100gr) | T2: (mg) | U2: (mg)
A3: Cantidad | B3: Cereals i derivats
A4: 70 | B4: Arroz Blanco, Crudo | C4: 10 | D4: 362 | E4: 6.8 | F4: 0.9 | G4: 81.6 | H4: 5 | I4: 106 | J4: 120 | K4: 14 | L4: 0.7 | M4: 0 | N4: 0.06 | O4: 0.04 | P4: 2.3 | Q4: 0 | R4: 0 | S4: 0.13 | T4: 0 | U4: 33
B5: Arroz Integral, Crudo | C5: 14 | D5: 355 | E5: 8 | F5: 3 | G5: 74 | H5: 6 | I5: 223 | J5: 120 | K5: 21 | L5: 1.7 | M5: 0 | N5: 0.39 | O5: 0.08 | P5: 4.8 | Q5: 0 | R5: 0 | S5: 0.15 | T5: 0 | U5: 143
B6: Arroz Integral, Cocido | C6: 72 | D6: 112 | E6: 2.6 | F6: 0.4 | G6: 24.2 | H6: 3 | I6: 43 | J6: 83 | K6: 10 | L6: 0.48 | M6: 0 | N6: 0.1 | O6: 0.02 | Q6: 0 | R6: 0 | S6: 0.06 | T6: 0 | U6: 0.43
B7: Tortitas de arroz | C7: 5 | D7: 387 | E7: 8.2 | F7: 2.8 | G7: 81.5 | H7: 326 | I7: 290 | J7: 360 | K7: 11 | L7: 1.49 | M7: 0 | N7: 0.06 | O7: 0.16 | P7: 7.8 | Q7: 0 | R7: 0 | S7: 1 | T7: 0 | U7: 131
B8: Pan Blanco | C8: 35 | D8: 260 | E8: 7.5 | F8: 1.2 | G8: 55 | H8: 600 | I8: 120 | J8: 100 | K8: 56 | L8: 1.2 | M8: 0 | N8: 0.08 | O8: 0.05 | P8: 1 | Q8: 0 | R8: 0 | S8: 0.18 | T8: 0 | U8: 25
B9: Pan Integral | C9: 40 | D9: 240 | E9: 8.5 | F9: 1.5 | G9: 48 | H9: 650 | I9: 225 | J9: 195 | K9: 58 | L9: 2 | M9: 0 | N9: 0.3 | O9: 0.14 | P9: 3.4 | Q9: 0 | R9: 0 | S9: 0.2 | T9: 0 | U9: 81
B10: Biscottes | C10: 10 | D10: 376 | E10: 10 | F10: 4 | G10: 75 | H10: 263 | I10: 160 | J10: 120 | K10: 36 | L10: 1.3 | M10: 0 | N10: 0.07 | O10: 0.06 | P10: 1 | Q10: 0 | R10: 0 | S10: 0.3 | T10: 0 | U10: 18
B11: Galleta Maria | C11: 4 | D11: 450 | E11: 7 | F11: 14 | G11: 74 | H11: 250 | I11: 110 | J11: 97 | K11: 30 | L11: 1.5 | M11: 0 | N11: 0.1 | O11: 0.08 | P11: 2.1 | Q11: 30 | R11: 50 | S11: 0.3 | T11: 0 | U11: 25
B12: Pasta, Cruda | C12: 11 | D12: 356 | E12: 12.5 | F12: 1.2 | G12: 74 | H12: 5 | I12: 200 | J12: 100 | K12: 23 | L12: 1.3 | M12: 0 | N12: 0.1 | O12: 0.05 | P12: 2 | Q12: 0 | R12: 0 | S12: 0.18 | T12: 0 | U12: 55
B13: Cereales Desayuno | C13: 4 | D13: 391 | E13: 7 | F13: 1.2 | G13: 87 | H13: 640 | I13: 140 | J13: 90 | K13: 20 | L13: 8.5 | M13: 0 | N13: 1.3 | O13: 1.5 | P13: 18 | Q13: 0 | R13: 0 | S13: 0.45 | T13: 0 | U13: 25
A14: 100 | B14: Avena | C14: 9 | D14: 348 | E14: 15 | F14: 6.4 | G14: 57.7 | H14: 4 | I14: 350 | J14: 420 | K14: 53 | L14: 4.2 | M14: 0 | N14: 0.5 | O14: 0.14 | P14: 0.8 | Q14: 0 | R14: 0 | S14: 0.25 | T14: 0 | U14: 148
B15: Weetabix | C15: 10 | D15: 338 | E15: 11.5 | F15: 2 | G15: 68.4 | H15: 260 | I15: 0 | J15: 0 | K15: 0 | L15: 11.9 | M15: 0 | N15: 1.2 | O15: 1.4 | P15: 15.3 | Q15: 0 | R15: 0 | S15: 0.63 | T15: 0 | U15: 0
B16: Quinoa | C16: 13 | D16: 318 | E16: 12 | F16: 6 | G16: 49 | H16: 61 | I16: 782 | J16: 230 | K16: 79 | L16: 7.8 | M16: 0 | N16: 0.2 | O16: 0.4 | P16: 2.9 | Q16: 0 | R16: 0 | S16: 0.8 | T16: 0 | U16: 210
B17: Muesli | C17: 13 | D17: 419 | E17: 10 | F17: 12 | G17: 65 | H17: 200 | I17: 440 | J17: 310 | K17: 63 | L17: 4.8 | M17: 0 | N17: 0.55 | O17: 0.48 | P17: 4.1 | Q17: 0 | R17: 0 | S17: 0.16 | T17: 0 | U17: 100
C19: Aigua | D19: Calories | E19: Proteïna | F19: Lípids totals | G19: Glúcids totals | H19: Sodi: Na | I19: Potassi: K | J19: Fósfor: P | K19: Calci: Ca | L19: Ferro: Fe | M19: Vitamina C | N19: Tiamina | O19: Riboflavina | P19: Niacina | Q19: Carotens | R19: Retinol | S19: Preu | T19: Colesterol | U19: Magnesi
C20: (g) | D20: (Kcal) | E20: (g) | F20: ((g) | G20: (g) | H20: (mg) | I20: (mg) | J20: (mg) | K20: (mg) | L20: (mg) | M20: (mg) | N20: (mg) | O20: (mg) | P20: (mg) | Q20: (microg.) | R20: (microg.) | S20: (euros/100gr) | T20: (mg) | U20: (mg)
A21: Cantidad | B21: Llegums seques
B22: Judias, en seco | C22: 1 | D22: 319 | E22: 21.5 | F22: 1.5 | G22: 54.8 | H22: 30 | I22: 1225 | J22: 360 | K22: 130 | L22: 6.5 | M22: 3.4 | N22: 0.5 | O22: 0.17 | P22: 2.4 | Q22: 0 | R22: 0 | S22: 0.15 | T22: 0 | U22: 135
B23: Lentejas, en seco | C23: 9.2 | D23: 327 | E23: 23.2 | F23: 1.7 | G23: 54.8 | H23: 36 | I23: 700 | J23: 300 | K23: 70 | L23: 8 | M23: 3.4 | N23: 0.47 | O23: 0.2 | P23: 2.5 | Q23: 60 | R23: 0 | S23: 0.15 | T23: 0 | U23: 74
B24: Garbanzos, en seco | C24: 4.7 | D24: 356 | E24: 20.8 | F24: 5.5 | G24: 55.8 | H24: 34 | I24: 900 | J24: 335 | K24: 143 | L24: 7 | M24: 4.1 | N24: 0.45 | O24: 0.15 | P24: 1.7 | Q24: 198 | R24: 0 | S24: 0.15 | T24: 0 | U24: 122
B25: Guisante congelado, crudo | C25: 84 | D25: 71 | E25: 5 | F25: 1 | G25: 9 | H25: 3 | I25: 197 | J25: 91 | K25: 24 | L25: 1.6 | M25: 18 | N25: 0.26 | O25: 0.1 | P25: 1.7 | Q25: 360 | R25: 0 | S25: 0.39 | T25: 0 | U25: 26
B26: Judias en conserva (bote) | C26: 76 | D26: 101 | E26: 7 | F26: 0 | G26: 16 | H26: 4 | I26: 362 | J26: 84 | K26: 71 | L26: 2.8 | M26: 0 | N26: 0.1 | O26: 0.04 | P26: 0.1 | Q26: 0 | R26: 0 | S26: 0.23 | T26: 0 | U26: 39
B27: Lentejas en conserva (bote) | C27: 79.37 | D27: 74 | E27: 6.28 | F27: 0.21 | G27: 11.4 | H27: 446 | I27: 143 | J27: 58 | K27: 18.89 | L27: 1.58 | M27: 0 | N27: 0.07 | O27: 0.06 | P27: 0.3 | Q27: 0.83 | R27: 0 | S27: 0.23 | T27: 0 | U27: 15.4
B28: Garbanzos en conserva (bote) | C28: 68 | D28: 154 | E28: 9 | F28: 3 | G28: 19 | H28: 6 | I28: 335 | J28: 132 | K28: 56 | L28: 2.8 | M28: 0 | N28: 0 | O28: 0 | P28: 0 | Q28: 0 | R28: 0 | S28: 0.23 | T28: 0 | U28: 0

Sheet Verduras y Frutas
C1: Aigua | D1: Calories | E1: Proteïna | F1: Lípids totals | G1: Glúcids totals | H1: Sodi: Na | I1: Potassi: K | J1: Fósfor: P | K1: Calci: Ca | L1: Ferro: Fe | M1: Vitamina C | N1: Tiamina | O1: Riboflavina | P1: Niacina | Q1: Carotens | R1: Retinol | S1: Preu | T1: Colesterol | U1: Magnesi
C2: (g) | D2: (Kcal) | E2: (g) | F2: ((g) | G2: (g) | H2: (mg) | I2: (mg) | J2: (mg) | K2: (mg) | L2: (mg) | M2: (mg) | N2: (mg) | O2: (mg) | P2: (mg) | Q2: (microg.) | R2: (microg.) | S2: (euros/100gr) | T2: (mg) | U2: (mg)
A3: Cantidad | B3: Verdures
A4: 250 | B4: Patatas | C4: 79 | D4: 82 | E4: 2.2 | F4: 0.2 | G4: 18 | H4: 7 | I4: 330 | J4: 29 | K4: 10 | L4: 0.8 | M4: 4 | N4: 0.1 | O4: 0.04 | P4: 1.3 | Q4: 0 | R4: 0 | S4: 0.1 | T4: 0 | U4: 20
B5: Zanahoria | C5: 90 | D5: 30 | E5: 0.9 | F5: 0.3 | G5: 6 | H5: 50 | I5: 300 | J5: 33 | K5: 34 | L5: 0.5 | M5: 8 | N5: 0.05 | O5: 0.05 | P5: 0.5 | Q5: 10000 | R5: 0 | S5: 0.1 | T5: 0 | U5: 10
B6: Coles y Verduras de hoja | C6: 93.3 | D6: 20 | E6: 1.4 | F6: 0.2 | G6: 3.2 | H6: 15 | I6: 225 | J6: 50 | K6: 40 | L6: 0.5 | M6: 30 | N6: 0.05 | O6: 0.04 | P6: 0.03 | Q6: 300 | R6: 0 | S6: 0.13 | T6: 0 | U6: 13
B7: Brocoli | C7: 89 | D7: 34 | E7: 2.8 | F7: 0.4 | G7: 7 | H7: 33 | I7: 325 | J7: 66 | K7: 48 | L7: 0.7 | M7: 89 | N7: 0.06 | O7: 0.12 | P7: 0.63 | Q7: 3000 | R7: 0 | S7: 0.16 | T7: 0 | U7: 21
B8: Lechuga, endivias y escarolas | C8: 95.2 | D8: 17 | E8: 1.4 | F8: 0.3 | G8: 2 | H8: 8 | I8: 300 | J8: 30 | K8: 54 | L8: 1 | M8: 12.2 | N8: 0.07 | O8: 0.1 | P8: 0.4 | Q8: 1100 | R8: 0 | S8: 0.35 | T8: 0 | U8: 10
B9: Esparragos | C9: 93 | D9: 20 | E9: 2.2 | F9: 0.12 | G9: 3.88 | H9: 2 | I9: 202 | J9: 52 | K9: 24 | L9: 2.14 | M9: 5.6 | N9: 0.14 | O9: 0.14 | P9: 0.97 | Q9: 0 | R9: 0 | S9: 0.5 | T9: 0 | U9: 14
B10: Tomate | C10: 94.5 | D10: 19 | E10: 0.9 | F10: 0.2 | G10: 3.5 | H10: 5 | I10: 250 | J10: 25 | K10: 11 | L10: 0.7 | M10: 26.6 | N10: 0.07 | O10: 0.04 | P10: 0.6 | Q10: 600 | R10: 0 | S10: 0.2 | T10: 0 | U10: 10
B11: Guisantes | C11: 80.1 | D11: 72 | E11: 5.1 | F11: 0.4 | G11: 12 | H11: 4 | I11: 250 | J11: 100 | K11: 25 | L11: 1.5 | M11: 13 | N11: 0.25 | O11: 0.15 | P11: 1.5 | Q11: 300 | R11: 0 | S11: 0.25 | T11: 0 | U11: 34
A12: 200 | B12: Judias Verdes (cocidas) | C12: 91.5 | D12: 31 | E12: 2 | F12: 0.2 | G12: 5.4 | H12: 3 | I12: 212 | J12: 28 | K12: 40 | L12: 0.9 | M12: 9 | N12: 0.06 | O12: 0.08 | P12: 0.5 | Q12: 400 | R12: 0 | S12: 0.25 | T12: 0 | U12: 25
B13: Cebolla | C13: 91 | D13: 34 | E13: 1.3 | F13: 0.2 | G13: 6.8 | H13: 6 | I13: 160 | J13: 36 | K13: 30 | L13: 0.4 | M13: 12 | N13: 0.05 | O13: 0.05 | P13: 0.4 | Q13: 20 | R13: 0 | S13: 0.1 | T13: 0 | U13: 7
B14: Pimiento | C14: 93 | D14: 21 | E14: 1.1 | F14: 0.3 | G14: 3.5 | H14: 5 | I14: 205 | J14: 26 | K14: 9 | L14: 0.6 | M14: 126 | N14: 0.06 | O14: 0.05 | P14: 0.7 | Q14: 750 | R14: 0 | S14: 0.18 | T14: 0 | U14: 10
B15: Berenjena, Pepino, Calabacin | C15: 93.5 | D15: 19 | E15: 1 | F15: 0.2 | G15: 3.2 | H15: 5 | I15: 210 | J15: 20 | K15: 12 | L15: 0.4 | M15: 1.5 | N15: 0.06 | O15: 0.03 | P15: 0.6 | Q15: 26 | R15: 0 | S15: 0.1 | T15: 0 | U15: 12
B16: Champiñones | C16: 92 | D16: 33 | E16: 3 | F16: 0.3 | G16: 4 | H16: 15 | I16: 414 | J16: 116 | K16: 6 | L16: 0.8 | M16: 4 | N16: 0.1 | O16: 0.31 | P16: 5.3 | Q16: 0 | R16: 0 | S16: 0.5 | T16: 0 | U16: 12
B17: Ensalada Verde (lechuga, tomate, cebolla, pepino) | C17: 95 | D17: 20 | E17: 1 | F17: 0 | G17: 3 | H17: 14 | I17: 203 | J17: 24 | K17: 22 | L17: 0.5 | M17: 11 | N17: 0.04 | O17: 0.04 | P17: 0.5 | Q17: 317 | R17: 0 | S17: 0.24 | T17: 0 | U17: 10
B18: Crema de Verduras | C18: 88.3 | D18: 58 | E18: 1.71 | F18: 3.15 | G18: 4.87 | H18: 273 | I18: 271 | J18: 12 | K18: 59 | L18: 1 | M18: 12 | N18: 0.05 | O18: 0.04 | P18: 0.5 | Q18: 317 | R18: 0 | S18: 0.27 | T18: 0 | U18: 25
B19: Menestra de Verduras | C19: 89.6 | D19: 45 | E19: 3.3 | F19: 0 | G19: 6.6 | H19: 96 | I19: 130 | J19: 57 | K19: 35 | L19: 0.8 | M19: 13 | N19: 0.12 | O19: 0.09 | P19: 0.5 | Q19: 420 | R19: 0 | S19: 0.19 | T19: 0 | U19: 16
B20: Gazpacho | C20: 94.8 | D20: 34 | E20: 0.6 | F20: 2.6 | G20: 1.6 | H20: 303 | I20: 92 | J20: 15 | K20: 10 | L20: 0.4 | M20: 2.9 | N20: 0.02 | O20: 0.01 | P20: 0.51 | Q20: 53 | R20: 0 | S20: 0.15 | T20: 0 | U20: 3
C22: Aigua | D22: Calories | E22: Proteïna | F22: Lípids totals | G22: Glúcids totals | H22: Sodi: Na | I22: Potassi: K | J22: Fósfor: P | K22: Calci: Ca | L22: Ferro: Fe | M22: Vitamina C | N22: Tiamina | O22: Riboflavina | P22: Niacina | Q22: Carotens | R22: Retinol | S22: Preu | T22: Colesterol | U22: Magnesi
C23: (g) | D23: (Kcal) | E23: (g) | F23: ((g) | G23: (g) | H23: (mg) | I23: (mg) | J23: (mg) | K23: (mg) | L23: (mg) | M23: (mg) | N23: (mg) | O23: (mg) | P23: (mg) | Q23: (microg.) | R23: (microg.) | S23: (euros/100gr) | T23: (mg) | U23: (mg)
A24: Cantidad | B24: Fruita
A25: 150 | B25: Citricos y Kiwi | C25: 88.2 | D25: 46 | E25: 1 | F25: 0.2 | G25: 10 | H25: 3 | I25: 200 | J25: 24 | K25: 41 | L25: 0.5 | M25: 50.6 | N25: 0.08 | O25: 0.04 | P25: 0.4 | Q25: 202 | R25: 0 | S25: 0.25 | T25: 0 | U25: 14
B26: Fruites con hues (melocotones, albaricoques, cerezas) | C26: 85 | D26: 50 | E26: 0.7 | F26: 0.2 | G26: 11.4 | H26: 1 | I26: 310 | J26: 23 | K26: 17 | L26: 0.4 | M26: 7 | N26: 0.05 | O26: 0.05 | P26: 0.4 | Q26: 180 | R26: 0 | S26: 0.2 | T26: 0 | U26: 8
B27: Manzanas, Peras | C27: 87 | D27: 46 | E27: 0.3 | F27: 0.3 | G27: 10.5 | H27: 2 | I27: 120 | J27: 11 | K27: 9 | L27: 0.4 | M27: 7 | N27: 0.04 | O27: 0.03 | P27: 0.2 | Q27: 43 | R27: 0 | S27: 0.19 | T27: 0 | U27: 5
B28: Uva | C28: 82 | D28: 73 | E28: 0.7 | F28: 0.7 | G28: 16 | H28: 2 | I28: 250 | J28: 22 | K28: 17 | L28: 0.3 | M28: 4 | N28: 0.04 | O28: 0.02 | P28: 0.3 | Q28: 23 | R28: 0 | S28: 0.39 | T28: 0 | U28: 4
A29: 100 | B29: Platanos | C29: 76 | D29: 88 | E29: 1.2 | F29: 0.4 | G29: 20 | H29: 3 | I29: 380 | J29: 28 | K29: 9 | L29: 0.5 | M29: 10 | N29: 0.05 | O29: 0.07 | P29: 0.6 | Q29: 238 | R29: 0 | S29: 0.15 | T29: 0 | U29: 33
B30: Higos | C30: 85 | D30: 55 | E30: 1 | F30: 0.2 | G30: 12.3 | H30: 3 | I30: 250 | J30: 25 | K30: 42 | L30: 0.5 | M30: 5 | N30: 0.05 | O30: 0.05 | P30: 0.4 | Q30: 60 | R30: 0 | S30: 0.4 | T30: 0 | U30: 18
B31: Melón y Sandia | C31: 90 | D31: 31 | E31: 0.6 | F31: 0.2 | G31: 6.7 | H31: 14 | I31: 320 | J31: 30 | K31: 16 | L31: 0.4 | M31: 25 | N31: 0.05 | O31: 0.03 | P31: 0.6 | Q31: 671 | R31: 0 | S31: 0.1 | T31: 0 | U31: 13
B32: Piña Fresca | C32: 85 | D32: 53 | E32: 0.5 | F32: 0.3 | G32: 12 | H32: 2 | I32: 250 | J32: 11 | K32: 11 | L32: 0.4 | M32: 25 | N32: 0.07 | O32: 0.05 | P32: 0.3 | Q32: 32 | R32: 0 | S32: 0.12 | T32: 0 | U32: 15
A33: 20 | B33: Aguacate | C33: 76.4 | D33: 138 | E33: 1.8 | F33: 14.2 | G33: 0.8 | H33: 7 | I33: 522 | J33: 44 | K33: 16 | L33: 1 | M33: 11 | N33: 0.07 | O33: 0.16 | P33: 2 | Q33: 185 | R33: 0 | S33: 0.34 | T33: 0 | U33: 33

Sheet Frutos Secos y Aceites
C1: Aigua | D1: Calories | E1: Proteïna | F1: Lípids totals | G1: Glúcids totals | H1: Sodi: Na | I1: Potassi: K | J1: Fósfor: P | K1: Calci: Ca | L1: Ferro: Fe | M1: Vitamina C | N1: Tiamina | O1: Riboflavina | P1: Niacina | Q1: Carotens | R1: Retinol | S1: Preu | T1: Colesterol | U1: Magnesi
C2: (g) | D2: (Kcal) | E2: (g) | F2: ((g) | G2: (g) | H2: (mg) | I2: (mg) | J2: (mg) | K2: (mg) | L2: (mg) | M2: (mg) | N2: (mg) | O2: (mg) | P2: (mg) | Q2: (microg.) | R2: (microg.) | S2: (euros/100gr) | T2: (mg) | U2: (mg)
A3: Cantidad | B3: Frutos Secos y Deshidratada- Fruita seca i Deshidratada
B4: Dátiles | C4: 19 | D4: 287 | E4: 2 | F4: 0.1 | G4: 70 | H4: 5 | I4: 750 | J4: 64 | K4: 68 | L4: 1.6 | M4: 3 | N4: 0.07 | O4: 0.04 | P4: 2 | Q4: 50 | R4: 0 | S4: 0.64 | T4: 0 | U4: 58
B5: Higos,secos | C5: 16.8 | D5: 260 | E5: 3.6 | F5: 1 | G5: 60 | H5: 40 | I5: 983 | J5: 108 | K5: 200 | L5: 4.2 | M5: 0 | N5: 0.1 | O5: 0.08 | P5: 1.7 | Q5: 50 | R5: 0 | S5: 0.68 | T5: 0 | U5: 62
B6: Ciruelas, secas | C6: 39 | D6: 172 | E6: 2.5 | F6: 0.3 | G6: 40 | H6: 12 | I6: 950 | J6: 95 | K6: 45 | L6: 2.9 | M6: 1.5 | N6: 0.1 | O6: 0.2 | P6: 1.7 | Q6: 570 | R6: 0 | S6: 0.68 | T6: 0 | U6: 40
B7: Almendas, Avellanas, Nueces | C7: 5 | D7: 550 | E7: 15 | F7: 50 | G7: 10 | H7: 5 | I7: 700 | J7: 470 | K7: 250 | L7: 4 | M7: 0 | N7: 0.23 | O7: 0.75 | P7: 2.5 | Q7: 0 | R7: 0 | S7: 0.95 | T7: 0 | U7: 200
B8: Cacahuetes y Almendras Salados | C8: 2.6 | D8: 598 | E8: 25 | F8: 50 | G8: 12 | H8: 430 | I8: 720 | J8: 387 | K8: 62 | L8: 2.5 | M8: 0 | N8: 0.25 | O8: 0.12 | P8: 15 | Q8: 0 | R8: 0 | S8: 0.8 | T8: 0 | U8: 200
B9: Castañas | C9: 51.7 | D9: 172 | E9: 2 | F9: 2.7 | G9: 35 | H9: 11 | I9: 500 | J9: 74 | K9: 46 | L9: 0.9 | M9: 0 | N9: 0.2 | O9: 0.22 | P9: 0.3 | Q9: 0 | R9: 0 | S9: 0.8 | T9: 0 | U9: 33
B10: Pasas | C10: 30 | D10: 292 | E10: 3 | F10: 1 | G10: 66 | H10: 23 | I10: 783 | J10: 85 | K10: 40 | L10: 2.4 | M10: 4 | N10: 0.11 | O10: 0.14 | P10: 0.9 | Q10: 11 | R10: 0 | S10: 0.63 | T10: 0 | U10: 31
C17: Aigua | D17: Calories | E17: Proteïna | F17: Lípids totals | G17: Glúcids totals | H17: Sodi: Na | I17: Potassi: K | J17: Fósfor: P | K17: Calci: Ca | L17: Ferro: Fe | M17: Vitamina C | N17: Tiamina | O17: Riboflavina | P17: Niacina | Q17: Carotens | R17: Retinol | S17: Preu | T17: Colesterol | U17: Magnesi
C18: (g) | D18: (Kcal) | E18: (g) | F18: ((g) | G18: (g) | H18: (mg) | I18: (mg) | J18: (mg) | K18: (mg) | L18: (mg) | M18: (mg) | N18: (mg) | O18: (mg) | P18: (mg) | Q18: (microg.) | R18: (microg.) | S18: (euros/100gr) | T18: (mg) | U18: (mg)
A19: Cantidad | B19: Olis i greixos
B20: Manteca | C20: 0.2 | D20: 891 | E20: 0 | F20: 99 | G20: 0 | H20: 2 | I20: 1 | J20: 3 | K20: 1 | L20: 0 | M20: 0 | N20: 0 | O20: 0 | P20: 0.3 | R20: 9 | S20: 0.5 | T20: 95 | U20: 1
B21: Aceite de Oliva | C21: 0.2 | D21: 899 | E21: 0 | F21: 99.9 | G21: 0 | H21: 2 | I21: 0 | J21: 0 | K21: 1 | L21: 0 | M21: 0 | N21: 0 | O21: 0 | P21: 0 | Q21: 0 | R21: 0 | S21: 0.3 | T21: 0 | U21: 0
B22: Aceite de Girasol | C22: 0.2 | D22: 899 | E22: 0 | F22: 99.9 | G22: 0 | H22: 0 | I22: 0 | J22: 0 | K22: 0 | L22: 0.03 | M22: 0 | N22: 0 | O22: 0 | P22: 0 | Q22: 0 | R22: 0 | S22: 0.12 | T22: 0 | U22: 0
B23: Margarina vegetal | C23: 19.2 | D23: 753 | E23: 0 | F23: 83.5 | G23: 0.4 | H23: 118 | I23: 5 | J23: 12 | K23: 10 | L23: 0 | M23: 0 | N23: 0.01 | O23: 0.01 | P23: 0 | Q23: 570 | R23: 900 | S23: 0.4 | T23: 0 | U23: 2
B24: Nata | C24: 59.3 | D24: 316 | E24: 2.3 | F24: 33.4 | G24: 1.6 | H24: 35 | I24: 100 | J24: 58 | K24: 80 | L24: 0.2 | M24: 0 | N24: 0.01 | O24: 0.1 | P24: 0.1 | Q24: 340 | R24: 250 | S24: 0.25 | T24: 90 | U24: 4
B25: Mantequilla | C25: 15.5 | D25: 751 | E25: 0.7 | F25: 83 | G25: 0.4 | H25: 22 | I25: 12 | J25: 15 | K25: 15 | L25: 0.2 | M25: 0 | N25: 0.01 | O25: 0.02 | P25: 0.03 | Q25: 505 | R25: 708 | S25: 0.55 | T25: 250 | U25: 2
B26: Aceituna verde en salmuera | C26: 76.8 | D26: 110 | E26: 1.1 | F26: 11.8 | G26: 0 | H26: 1930 | I26: 72 | J26: 16 | K26: 48 | L26: 1.1 | M26: 0 | N26: 0.01 | O26: 0.04 | P26: 0.25 | Q26: 208 | R26: 0 | S26: 0.5 | T26: 0 | U26: 22
B27: Mayonesa Light | C27: 48.9 | D27: 394 | E27: 1 | F27: 38.5 | G27: 10.8 | H27: 750 | I27: 10 | J27: 50 | K27: 10 | L27: 0.3 | M27: 0 | N27: 0.02 | O27: 0.05 | P27: 0.01 | Q27: 0 | R27: 0 | S27: 0.3 | T27: 50 | U27: 1

Sheet Azucares y Bebidas
C1: Aigua | D1: Calories | E1: Proteïna | F1: Lípids totals | G1: Glúcids totals | H1: Sodi: Na | I1: Potassi: K | J1: Fósfor: P | K1: Calci: Ca | L1: Ferro: Fe | M1: Vitamina C | N1: Tiamina | O1: Riboflavina | P1: Niacina | Q1: Carotens | R1: Retinol | S1: Preu | T1: Colesterol | U1: Magnesi
C2: (g) | D2: (Kcal) | E2: (g) | F2: ((g) | G2: (g) | H2: (mg) | I2: (mg) | J2: (mg) | K2: (mg) | L2: (mg) | M2: (mg) | N2: (mg) | O2: (mg) | P2: (mg) | Q2: (microg.) | R2: (microg.) | S2: (euros/100gr) | T2: (mg) | U2: (mg)
A3: Cantidad | B3: Productes ensucrats, cacau i xocolata
B4: Azúcar, caramelos | C4: 0.1 | D4: 400 | E4: 0 | F4: 0 | G4: 100 | H4: 0 | I4: 2 | J4: 0 | K4: 0 | L4: 0 | M4: 0 | N4: 0 | O4: 0 | P4: 0 | Q4: 0 | R4: 0 | S4: 0.5 | T4: 0 | U4: 1
B5: Mermelada | C5: 30 | D5: 278 | E5: 0.5 | F5: 0 | G5: 69 | H5: 14 | I5: 105 | J5: 14 | K5: 12 | L5: 0.6 | M5: 5 | N5: 0 | O5: 0 | P5: 0 | Q5: 0 | R5: 0 | S5: 0.4 | T5: 0 | U5: 6
B6: Miel | C6: 23 | D6: 301 | E6: 0.4 | F6: 0 | G6: 75 | H6: 7 | I6: 36 | J6: 17 | K6: 5 | L6: 0.4 | M6: 0 | N6: 0 | O6: 0.05 | P6: 0.2 | Q6: 0 | R6: 0 | S6: 0.5 | T6: 0 | U6: 5
A7: 15 | B7: Cacao en polvo | C7: 3 | D7: 383 | E7: 6 | F7: 6 | G7: 76.2 | H7: 200 | I7: 550 | J7: 210 | K7: 40 | L7: 3.7 | M7: 0 | N7: 0.04 | O7: 0.04 | P7: 0.7 | Q7: 0 | R7: 0 | S7: 0.55 | T7: 0 | U7: 160
B8: Chocolate con Leche y azucar | C8: 1.4 | D8: 546 | E8: 8 | F8: 32 | G8: 56.5 | H8: 100 | I8: 440 | J8: 255 | K8: 220 | L8: 1.8 | M8: 0 | N8: 0.1 | O8: 0.35 | P8: 0.5 | Q8: 40 | R8: 0 | S8: 0.8 | T8: 18 | U8: 42
B9: Donut Comercial | C9: 23 | D9: 412 | E9: 6 | F9: 24.5 | G9: 42 | H9: 225 | I9: 90 | J9: 95 | K9: 35 | L9: 1.6 | M9: 0 | N9: 0.14 | O9: 0.1 | P9: 0.95 | Q9: 270 | R9: 180 | S9: 1.1 | T9: 21 | U9: 14
B10: Croissant | C10: 14.8 | D10: 405 | E10: 7.5 | F10: 17.2 | G10: 55 | H10: 492 | I10: 201 | J10: 160 | K10: 42 | L10: 1.2 | M10: 0 | N10: 0.3 | O10: 0.2 | P10: 2.3 | Q10: 70 | R10: 21 | S10: 0.78 | T10: 50 | U10: 16
C17: Aigua | D17: Calories | E17: Proteïna | F17: Lípids totals | G17: Glúcids totals | H17: Sodi: Na | I17: Potassi: K | J17: Fósfor: P | K17: Calci: Ca | L17: Ferro: Fe | M17: Vitamina C | N17: Tiamina | O17: Riboflavina | P17: Niacina | Q17: Carotens | R17: Retinol | S17: Preu | T17: Colesterol | U17: Magnesi
C18: (g) | D18: (Kcal) | E18: (g) | F18: ((g) | G18: (g) | H18: (mg) | I18: (mg) | J18: (mg) | K18: (mg) | L18: (mg) | M18: (mg) | N18: (mg) | O18: (mg) | P18: (mg) | Q18: (microg.) | R18: (microg.) | S18: (euros/100gr) | T18: (mg) | U18: (mg)
A19: Cantidad | B19: Begudes
B20: Horchata | C20: 77.8 | D20: 99 | E20: 1.2 | F20: 2.7 | G20: 17.4 | H20: 70 | I20: 250 | J20: 30 | K20: 25 | L20: 0.1 | M20: 2 | N20: 0.03 | O20: 0.1 | P20: 0.1 | Q20: 0 | R20: 0 | S20: 0.12 | T20: 0 | U20: 19
B21: Bebidas Carbonatadas Azucaradas | C21: 89 | D21: 42 | E21: 0 | F21: 0 | G21: 10.5 | H21: 9 | I21: 1 | J21: 10 | K21: 5 | L21: 0 | M21: 0 | N21: 0 | O21: 0 | P21: 0 | Q21: 0 | R21: 0 | S21: 0.15 | T21: 0 | U21: 1
B22: Zumos de Fruta | C22: 87.8 | D22: 48 | E22: 0.5 | F22: 0.5 | G22: 10.4 | H22: 5 | I22: 145 | J22: 15 | K22: 9 | L22: 0.3 | M22: 34 | N22: 0.07 | O22: 0.02 | P22: 0.3 | Q22: 80 | R22: 0 | S22: 0.2 | T22: 0 | U22: 8
B23: Zumos de Tomate | C23: 93.5 | D23: 20 | E23: 0.8 | F23: 0.1 | G23: 4 | H23: 270 | I23: 245 | J23: 18 | K23: 8 | L23: 0.6 | M23: 16 | N23: 0.05 | O23: 0.03 | P23: 0.7 | Q23: 540 | R23: 0 | S23: 0.2 | T23: 0 | U23: 10
B24: Cerveza y Sidra | C24: 94 | D24: 36 | E24: 0.3 | F24: 0.01 | G24: 3 | H24: 5 | I24: 30 | J24: 13 | K24: 6 | L24: 0.03 | M24: 0 | N24: 0.01 | O24: 0.02 | P24: 0.6 | Q24: 0 | R24: 0 | S24: 0.15 | T24: 0 | U24: 7
B25: Vino y Cava | C25: 91 | D25: 70 | E25: 0.2 | F25: 0 | G25: 2 | H25: 5 | I25: 100 | J25: 20 | K25: 7 | L25: 0.4 | M25: 0 | N25: 0.01 | O25: 0.02 | P25: 0.08 | Q25: 0 | R25: 0 | S25: 0.4 | T25: 0 | U25: 10
B26: Licores de Frutas y Similares | C26: 46 | D26: 263 | E26: 0.1 | F26: 0.1 | G26: 29.4 | H26: 6 | I26: 35 | J26: 20 | K26: 6 | L26: 0.07 | M26: 0 | N26: 0.01 | O26: 0.02 | P26: 0 | Q26: 0 | R26: 0 | S26: 0.4 | T26: 0 | U26: 6
B27: Cognac, whisky, ginebra y similares | C27: 64 | D27: 252 | E27: 0 | F27: 0 | G27: 0 | H27: 0.6 | I27: 2 | J27: 0 | K27: 0 | L27: 0 | M27: 0 | N27: 0 | O27: 0 | P27: 0 | Q27: 0 | R27: 0 | S27: 1.2 | T27: 0 | U27: 0

Sheet Càlculs
C1: Aigua | D1: Calories | E1: Proteïna | F1: Lípids totals | G1: Glúcids totals | H1: Sodi: Na | I1: Potassi: K | J1: Fósfor: P | K1: Calci: Ca | L1: Ferro: Fe | M1: Vitamina C | N1: Tiamina | O1: Riboflavina | P1: Niacina | Q1: Carotens | R1: Retinol | S1: Preu | T1: Colesterol | U1: Magnesi
C2: (g) | D2: (Kcal) | E2: (g) | F2: ((g) | G2: (g) | H2: (mg) | I2: (mg) | J2: (mg) | K2: (mg) | L2: (mg) | M2: (mg) | N2: (mg) | O2: (mg) | P2: (mg) | Q2: (microg.) | R2: (microg.) | S2: (euros/100gr) | T2: (mg) | U2: (mg)
A4: ='Carnes y Pescados'!A4 -> 0 | B4: ='Carnes y Pescados'!B4 -> Caballo | C4: ='Carnes y Pescados'!$A4*'Carnes y Pescados'!C4/100 -> 0 | D4: ='Carnes y Pescados'!$A4*'Carnes y Pescados'!D4/100 -> 0 | E4: ='Carnes y Pescados'!$A4*'Carnes y Pescados'!E4/100 -> 0 | F4: ='Carnes y Pescados'!$A4*'Carnes y Pescados'!F4/100 -> 0 | G4: ='Carnes y Pescados'!$A4*'Carnes y Pescados'!G4/100 -> 0 | H4: ='Carnes y Pescados'!$A4*'Carnes y Pescados'!H4/100 -> 0 | I4: ='Carnes y Pescados'!$A4*'Carnes y Pescados'!I4/100 -> 0 | J4: ='Carnes y Pescados'!$A4*'Carnes y Pescados'!J4/100 -> 0 | ... U4: ='Carnes y Pescados'!$A4*'Carnes y Pescados'!U4/100 -> 0
A5: ='Carnes y Pescados'!A5 -> 150 | B5: ='Carnes y Pescados'!B5 -> Ternera (Bistec) | C5: ='Carnes y Pescados'!$A5*'Carnes y Pescados'!C5/100 -> 102.3 | D5: ='Carnes y Pescados'!$A5*'Carnes y Pescados'!D5/100 -> 262.5 | E5: ='Carnes y Pescados'!$A5*'Carnes y Pescados'!E5/100 -> 28.5 | F5: ='Carnes y Pescados'!$A5*'Carnes y Pescados'!F5/100 -> 16.5 | G5: ='Carnes y Pescados'!$A5*'Carnes y Pescados'!G5/100 -> 0 | H5: ='Carnes y Pescados'!$A5*'Carnes y Pescados'!H5/100 -> 105 | I5: ='Carnes y Pescados'!$A5*'Carnes y Pescados'!I5/100 -> 540 | J5: ='Carnes y Pescados'!$A5*'Carnes y Pescados'!J5/100 -> 304.5 | ... U5: ='Carnes y Pescados'!$A5*'Carnes y Pescados'!U5/100 -> 30
A6: ='Carnes y Pescados'!A6 -> 0 | B6: ='Carnes y Pescados'!B6 -> Cordero | C6: ='Carnes y Pescados'!$A6*'Carnes y Pescados'!C6/100 -> 0 | D6: ='Carnes y Pescados'!$A6*'Carnes y Pescados'!D6/100 -> 0 | E6: ='Carnes y Pescados'!$A6*'Carnes y Pescados'!E6/100 -> 0 | F6: ='Carnes y Pescados'!$A6*'Carnes y Pescados'!F6/100 -> 0 | G6: ='Carnes y Pescados'!$A6*'Carnes y Pescados'!G6/100 -> 0 | H6: ='Carnes y Pescados'!$A6*'Carnes y Pescados'!H6/100 -> 0 | I6: ='Carnes y Pescados'!$A6*'Carnes y Pescados'!I6/100 -> 0 | J6: ='Carnes y Pescados'!$A6*'Carnes y Pescados'!J6/100 -> 0 | ... U6: ='Carnes y Pescados'!$A6*'Carnes y Pescados'!U6/100 -> 0
A7: ='Carnes y Pescados'!A7 -> 0 | B7: ='Carnes y Pescados'!B7 -> Cerdo (Lomo) | C7: ='Carnes y Pescados'!$A7*'Carnes y Pescados'!C7/100 -> 0 | D7: ='Carnes y Pescados'!$A7*'Carnes y Pescados'!D7/100 -> 0 | E7: ='Carnes y Pescados'!$A7*'Carnes y Pescados'!E7/100 -> 0 | F7: ='Carnes y Pescados'!$A7*'Carnes y Pescados'!F7/100 -> 0 | G7: ='Carnes y Pescados'!$A7*'Carnes y Pescados'!G7/100 -> 0 | H7: ='Carnes y Pescados'!$A7*'Carnes y Pescados'!H7/100 -> 0 | I7: ='Carnes y Pescados'!$A7*'Carnes y Pescados'!I7/100 -> 0 | J7: ='Carnes y Pescados'!$A7*'Carnes y Pescados'!J7/100 -> 0 | ... U7: ='Carnes y Pescados'!$A7*'Carnes y Pescados'!U7/100 -> 0
A8: ='Carnes y Pescados'!A8 -> 0 | B8: ='Carnes y Pescados'!B8 -> Conejo | C8: ='Carnes y Pescados'!$A8*'Carnes y Pescados'!C8/100 -> 0 | D8: ='Carnes y Pescados'!$A8*'Carnes y Pescados'!D8/100 -> 0 | E8: ='Carnes y Pescados'!$A8*'Carnes y Pescados'!E8/100 -> 0 | F8: ='Carnes y Pescados'!$A8*'Carnes y Pescados'!F8/100 -> 0 | G8: ='Carnes y Pescados'!$A8*'Carnes y Pescados'!G8/100 -> 0 | H8: ='Carnes y Pescados'!$A8*'Carnes y Pescados'!H8/100 -> 0 | I8: ='Carnes y Pescados'!$A8*'Carnes y Pescados'!I8/100 -> 0 | J8: ='Carnes y Pescados'!$A8*'Carnes y Pescados'!J8/100 -> 0 | ... U8: ='Carnes y Pescados'!$A8*'Carnes y Pescados'!U8/100 -> 0
A9: ='Carnes y Pescados'!A9 -> 150 | B9: ='Carnes y Pescados'!B9 -> Pollo, Pechuga sin Piel | C9: ='Carnes y Pescados'!$A9*'Carnes y Pescados'!C9/100 -> 111.9 | D9: ='Carnes y Pescados'!$A9*'Carnes y Pescados'!D9/100 -> 181.5 | E9: ='Carnes y Pescados'!$A9*'Carnes y Pescados'!E9/100 -> 30.75 | F9: ='Carnes y Pescados'!$A9*'Carnes y Pescados'!F9/100 -> 6.45 | G9: ='Carnes y Pescados'!$A9*'Carnes y Pescados'!G9/100 -> 0 | H9: ='Carnes y Pescados'!$A9*'Carnes y Pescados'!H9/100 -> 117 | I9: ='Carnes y Pescados'!$A9*'Carnes y Pescados'!I9/100 -> 450 | J9: ='Carnes y Pescados'!$A9*'Carnes y Pescados'!J9/100 -> 300 | ... U9: ='Carnes y Pescados'!$A9*'Carnes y Pescados'!U9/100 -> 34.5
A10: ='Carnes y Pescados'!A10 -> 0 | B10: ='Carnes y Pescados'!B10 -> Pavo, Fiambre | C10: ='Carnes y Pescados'!$A10*'Carnes y Pescados'!C10/100 -> 0 | D10: ='Carnes y Pescados'!$A10*'Carnes y Pescados'!D10/100 -> 0 | E10: ='Carnes y Pescados'!$A10*'Carnes y Pescados'!E10/100 -> 0 | F10: ='Carnes y Pescados'!$A10*'Carnes y Pescados'!F10/100 -> 0 | G10: ='Carnes y Pescados'!$A10*'Carnes y Pescados'!G10/100 -> 0 | H10: ='Carnes y Pescados'!$A10*'Carnes y Pescados'!H10/100 -> 0 | I10: ='Carnes y Pescados'!$A10*'Carnes y Pescados'!I10/100 -> 0 | J10: ='Carnes y Pescados'!$A10*'Carnes y Pescados'!J10/100 -> 0 | ... U10: ='Carnes y Pescados'!$A10*'Carnes y Pescados'!U10/100 -> 0
A11: ='Carnes y Pescados'!A11 -> 0 | B11: ='Carnes y Pescados'!B11 -> Ternera (Higado) | C11: ='Carnes y Pescados'!$A11*'Carnes y Pescados'!C11/100 -> 0 | D11: ='Carnes y Pescados'!$A11*'Carnes y Pescados'!D11/100 -> 0 | E11: ='Carnes y Pescados'!$A11*'Carnes y Pescados'!E11/100 -> 0 | F11: ='Carnes y Pescados'!$A11*'Carnes y Pescados'!F11/100 -> 0 | G11: ='Carnes y Pescados'!$A11*'Carnes y Pescados'!G11/100 -> 0 | H11: ='Carnes y Pescados'!$A11*'Carnes y Pescados'!H11/100 -> 0 | I11: ='Carnes y Pescados'!$A11*'Carnes y Pescados'!I11/100 -> 0 | J11: ='Carnes y Pescados'!$A11*'Carnes y Pescados'!J11/100 -> 0 | ... U11: ='Carnes y Pescados'!$A11*'Carnes y Pescados'!U11/100 -> 0
A12: ='Carnes y Pescados'!A12 -> 0 | B12: ='Carnes y Pescados'!B12 -> Jamón Cocido | C12: ='Carnes y Pescados'!$A12*'Carnes y Pescados'!C12/100 -> 0 | D12: ='Carnes y Pescados'!$A12*'Carnes y Pescados'!D12/100 -> 0 | E12: ='Carnes y Pescados'!$A12*'Carnes y Pescados'!E12/100 -> 0 | F12: ='Carnes y Pescados'!$A12*'Carnes y Pescados'!F12/100 -> 0 | G12: ='Carnes y Pescados'!$A12*'Carnes y Pescados'!G12/100 -> 0 | H12: ='Carnes y Pescados'!$A12*'Carnes y Pescados'!H12/100 -> 0 | I12: ='Carnes y Pescados'!$A12*'Carnes y Pescados'!I12/100 -> 0 | J12: ='Carnes y Pescados'!$A12*'Carnes y Pescados'!J12/100 -> 0 | ... U12: ='Carnes y Pescados'!$A12*'Carnes y Pescados'!U12/100 -> 0
A13: ='Carnes y Pescados'!A13 -> 0 | B13: ='Carnes y Pescados'!B13 -> Jamón Curado | C13: ='Carnes y Pescados'!$A13*'Carnes y Pescados'!C13/100 -> 0 | D13: ='Carnes y Pescados'!$A13*'Carnes y Pescados'!D13/100 -> 0 | E13: ='Carnes y Pescados'!$A13*'Carnes y Pescados'!E13/100 -> 0 | F13: ='Carnes y Pescados'!$A13*'Carnes y Pescados'!F13/100 -> 0 | G13: ='Carnes y Pescados'!$A13*'Carnes y Pescados'!G13/100 -> 0 | H13: ='Carnes y Pescados'!$A13*'Carnes y Pescados'!H13/100 -> 0 | I13: ='Carnes y Pescados'!$A13*'Carnes y Pescados'!I13/100 -> 0 | J13: ='Carnes y Pescados'!$A13*'Carnes y Pescados'!J13/100 -> 0 | ... U13: ='Carnes y Pescados'!$A13*'Carnes y Pescados'!U13/100 -> 0
A14: ='Carnes y Pescados'!A14 -> 0 | B14: ='Carnes y Pescados'!B14 -> Embutidos Curados (Chorizo, Salchichón) | C14: ='Carnes y Pescados'!$A14*'Carnes y Pescados'!C14/100 -> 0 | D14: ='Carnes y Pescados'!$A14*'Carnes y Pescados'!D14/100 -> 0 | E14: ='Carnes y Pescados'!$A14*'Carnes y Pescados'!E14/100 -> 0 | F14: ='Carnes y Pescados'!$A14*'Carnes y Pescados'!F14/100 -> 0 | G14: ='Carnes y Pescados'!$A14*'Carnes y Pescados'!G14/100 -> 0 | H14: ='Carnes y Pescados'!$A14*'Carnes y Pescados'!H14/100 -> 0 | I14: ='Carnes y Pescados'!$A14*'Carnes y Pescados'!I14/100 -> 0 | J14: ='Carnes y Pescados'!$A14*'Carnes y Pescados'!J14/100 -> 0 | ... U14: ='Carnes y Pescados'!$A14*'Carnes y Pescados'!U14/100 -> 0
A15: ='Carnes y Pescados'!A15 -> 0 | B15: ='Carnes y Pescados'!B15 -> Embutidos Cocidos (Butifarra, Salchichas) | C15: ='Carnes y Pescados'!$A15*'Carnes y Pescados'!C15/100 -> 0 | D15: ='Carnes y Pescados'!$A15*'Carnes y Pescados'!D15/100 -> 0 | E15: ='Carnes y Pescados'!$A15*'Carnes y Pescados'!E15/100 -> 0 | F15: ='Carnes y Pescados'!$A15*'Carnes y Pescados'!F15/100 -> 0 | G15: ='Carnes y Pescados'!$A15*'Carnes y Pescados'!G15/100 -> 0 | H15: ='Carnes y Pescados'!$A15*'Carnes y Pescados'!H15/100 -> 0 | I15: ='Carnes y Pescados'!$A15*'Carnes y Pescados'!I15/100 -> 0 | J15: ='Carnes y Pescados'!$A15*'Carnes y Pescados'!J15/100 -> 0 | ... U15: ='Carnes y Pescados'!$A15*'Carnes y Pescados'!U15/100 -> 0
... A18: ='Carnes y Pescados'!A18 -> 0 | B18: ='Carnes y Pescados'!B18 -> Hamburguesa de Pollo | C18: ='Carnes y Pescados'!$A18*'Carnes y Pescados'!C18/100 -> 0 | D18: ='Carnes y Pescados'!$A18*'Carnes y Pescados'!D18/100 -> 0 | E18: ='Carnes y Pescados'!$A18*'Carnes y Pescados'!E18/100 -> 0 | F18: ='Carnes y Pescados'!$A18*'Carnes y Pescados'!F18/100 -> 0 | G18: ='Carnes y Pescados'!$A18*'Carnes y Pescados'!G18/100 -> 0 | H18: ='Carnes y Pescados'!$A18*'Carnes y Pescados'!H18/100 -> 0 | I18: ='Carnes y Pescados'!$A18*'Carnes y Pescados'!I18/100 -> 0 | J18: ='Carnes y Pescados'!$A18*'Carnes y Pescados'!J18/100 -> 0 | ... U18: ='Carnes y Pescados'!$A18*'Carnes y Pescados'!U18/100 -> 0
C19: ='Carnes y Pescados'!$A19*'Carnes y Pescados'!C19/100 -> 0 | D19: ='Carnes y Pescados'!$A19*'Carnes y Pescados'!D19/100 -> 0 | E19: ='Carnes y Pescados'!$A19*'Carnes y Pescados'!E19/100 -> 0 | F19: ='Carnes y Pescados'!$A19*'Carnes y Pescados'!F19/100 -> 0 | G19: ='Carnes y Pescados'!$A19*'Carnes y Pescados'!G19/100 -> 0 | H19: ='Carnes y Pescados'!$A19*'Carnes y Pescados'!H19/100 -> 0 | I19: ='Carnes y Pescados'!$A19*'Carnes y Pescados'!I19/100 -> 0 | J19: ='Carnes y Pescados'!$A19*'Carnes y Pescados'!J19/100 -> 0 | ... U19: ='Carnes y Pescados'!$A19*'Carnes y Pescados'!U19/100 -> 0
A23: ='Carnes y Pescados'!A23 -> 0 | B23: ='Carnes y Pescados'!B23 -> Pescado Blanco (Merluza, Mero, Lenguado) | C23: ='Carnes y Pescados'!$A23*'Carnes y Pescados'!C23/100 -> 0 | D23: ='Carnes y Pescados'!$A23*'Carnes y Pescados'!D23/100 -> 0 | E23: ='Carnes y Pescados'!$A23*'Carnes y Pescados'!E23/100 -> 0 | F23: ='Carnes y Pescados'!$A23*'Carnes y Pescados'!F23/100 -> 0 | G23: ='Carnes y Pescados'!$A23*'Carnes y Pescados'!G23/100 -> 0 | H23: ='Carnes y Pescados'!$A23*'Carnes y Pescados'!H23/100 -> 0 | I23: ='Carnes y Pescados'!$A23*'Carnes y Pescados'!I23/100 -> 0 | J23: ='Carnes y Pescados'!$A23*'Carnes y Pescados'!J23/100 -> 0 | ... U23: ='Carnes y Pescados'!$A23*'Carnes y Pescados'!U23/100 -> 0
A24: ='Carnes y Pescados'!A24 -> 0 | B24: ='Carnes y Pescados'!B24 -> Pescado azul (Sardina, Caballa) | C24: ='Carnes y Pescados'!$A24*'Carnes y Pescados'!C24/100 -> 0 | D24: ='Carnes y Pescados'!$A24*'Carnes y Pescados'!D24/100 -> 0 | E24: ='Carnes y Pescados'!$A24*'Carnes y Pescados'!E24/100 -> 0 | F24: ='Carnes y Pescados'!$A24*'Carnes y Pescados'!F24/100 -> 0 | G24: ='Carnes y Pescados'!$A24*'Carnes y Pescados'!G24/100 -> 0 | H24: ='Carnes y Pescados'!$A24*'Carnes y Pescados'!H24/100 -> 0 | I24: ='Carnes y Pescados'!$A24*'Carnes y Pescados'!I24/100 -> 0 | J24: ='Carnes y Pescados'!$A24*'Carnes y Pescados'!J24/100 -> 0 | ... U24: ='Carnes y Pescados'!$A24*'Carnes y Pescados'!U24/100 -> 0
A25: ='Carnes y Pescados'!A25 -> 0 | B25: ='Carnes y Pescados'!B25 -> Crustaceos | C25: ='Carnes y Pescados'!$A25*'Carnes y Pescados'!C25/100 -> 0 | D25: ='Carnes y Pescados'!$A25*'Carnes y Pescados'!D25/100 -> 0 | E25: ='Carnes y Pescados'!$A25*'Carnes y Pescados'!E25/100 -> 0 | F25: ='Carnes y Pescados'!$A25*'Carnes y Pescados'!F25/100 -> 0 | G25: ='Carnes y Pescados'!$A25*'Carnes y Pescados'!G25/100 -> 0 | H25: ='Carnes y Pescados'!$A25*'Carnes y Pescados'!H25/100 -> 0 | I25: ='Carnes y Pescados'!$A25*'Carnes y Pescados'!I25/100 -> 0 | J25: ='Carnes y Pescados'!$A25*'Carnes y Pescados'!J25/100 -> 0 | ... U25: ='Carnes y Pescados'!$A25*'Carnes y Pescados'!U25/100 -> 0
A26: ='Carnes y Pescados'!A26 -> 0 | B26: ='Carnes y Pescados'!B26 -> Moluscos | C26: ='Carnes y Pescados'!$A26*'Carnes y Pescados'!C26/100 -> 0 | D26: ='Carnes y Pescados'!$A26*'Carnes y Pescados'!D26/100 -> 0 | E26: ='Carnes y Pescados'!$A26*'Carnes y Pescados'!E26/100 -> 0 | F26: ='Carnes y Pescados'!$A26*'Carnes y Pescados'!F26/100 -> 0 | G26: ='Carnes y Pescados'!$A26*'Carnes y Pescados'!G26/100 -> 0 | H26: ='Carnes y Pescados'!$A26*'Carnes y Pescados'!H26/100 -> 0 | I26: ='Carnes y Pescados'!$A26*'Carnes y Pescados'!I26/100 -> 0 | J26: ='Carnes y Pescados'!$A26*'Carnes y Pescados'!J26/100 -> 0 | ... U26: ='Carnes y Pescados'!$A26*'Carnes y Pescados'!U26/100 -> 0
A27: ='Carnes y Pescados'!A27 -> 0 | B27: ='Carnes y Pescados'!B27 -> Atún, lata aceite de oliva (escurrido) | C27: ='Carnes y Pescados'!$A27*'Carnes y Pescados'!C27/100 -> 0 | D27: ='Carnes y Pescados'!$A27*'Carnes y Pescados'!D27/100 -> 0 | E27: ='Carnes y Pescados'!$A27*'Carnes y Pescados'!E27/100 -> 0 | F27: ='Carnes y Pescados'!$A27*'Carnes y Pescados'!F27/100 -> 0 | G27: ='Carnes y Pescados'!$A27*'Carnes y Pescados'!G27/100 -> 0 | H27: ='Carnes y Pescados'!$A27*'Carnes y Pescados'!H27/100 -> 0 | I27: ='Carnes y Pescados'!$A27*'Carnes y Pescados'!I27/100 -> 0 | J27: ='Carnes y Pescados'!$A27*'Carnes y Pescados'!J27/100 -> 0 | ... U27: ='Carnes y Pescados'!$A27*'Carnes y Pescados'!U27/100 -> 0
A28: ='Carnes y Pescados'!A28 -> 0 | B28: ='Carnes y Pescados'!B28 -> Sardina, lata aceite oliva | C28: ='Carnes y Pescados'!$A28*'Carnes y Pescados'!C28/100 -> 0 | D28: ='Carnes y Pescados'!$A28*'Carnes y Pescados'!D28/100 -> 0 | E28: ='Carnes y Pescados'!$A28*'Carnes y Pescados'!E28/100 -> 0 | F28: ='Carnes y Pescados'!$A28*'Carnes y Pescados'!F28/100 -> 0 | G28: ='Carnes y Pescados'!$A28*'Carnes y Pescados'!G28/100 -> 0 | H28: ='Carnes y Pescados'!$A28*'Carnes y Pescados'!H28/100 -> 0 | I28: ='Carnes y Pescados'!$A28*'Carnes y Pescados'!I28/100 -> 0 | J28: ='Carnes y Pescados'!$A28*'Carnes y Pescados'!J28/100 -> 0 | ... U28: ='Carnes y Pescados'!$A28*'Carnes y Pescados'!U28/100 -> 0
A29: ='Carnes y Pescados'!A29 -> 0 | B29: ='Carnes y Pescados'!B29 -> Atún, lata al natural (escurrido) | C29: ='Carnes y Pescados'!$A29*'Carnes y Pescados'!C29/100 -> 0 | D29: ='Carnes y Pescados'!$A29*'Carnes y Pescados'!D29/100 -> 0 | E29: ='Carnes y Pescados'!$A29*'Carnes y Pescados'!E29/100 -> 0 | F29: ='Carnes y Pescados'!$A29*'Carnes y Pescados'!F29/100 -> 0 | G29: ='Carnes y Pescados'!$A29*'Carnes y Pescados'!G29/100 -> 0 | H29: ='Carnes y Pescados'!$A29*'Carnes y Pescados'!H29/100 -> 0 | I29: ='Carnes y Pescados'!$A29*'Carnes y Pescados'!I29/100 -> 0 | J29: ='Carnes y Pescados'!$A29*'Carnes y Pescados'!J29/100 -> 0 | ... U29: ='Carnes y Pescados'!$A29*'Carnes y Pescados'!U29/100 -> 0
A30: ='Carnes y Pescados'!A30 -> 0 | B30: ='Carnes y Pescados'!B30 -> Panga | C30: ='Carnes y Pescados'!$A30*'Carnes y Pescados'!C30/100 -> 0 | D30: ='Carnes y Pescados'!$A30*'Carnes y Pescados'!D30/100 -> 0 | E30: ='Carnes y Pescados'!$A30*'Carnes y Pescados'!E30/100 -> 0 | F30: ='Carnes y Pescados'!$A30*'Carnes y Pescados'!F30/100 -> 0 | G30: ='Carnes y Pescados'!$A30*'Carnes y Pescados'!G30/100 -> 0 | H30: ='Carnes y Pescados'!$A30*'Carnes y Pescados'!H30/100 -> 0 | I30: ='Carnes y Pescados'!$A30*'Carnes y Pescados'!I30/100 -> 0 | J30: ='Carnes y Pescados'!$A30*'Carnes y Pescados'!J30/100 -> 0 | ... U30: ='Carnes y Pescados'!$A30*'Carnes y Pescados'!U30/100 -> 0
A31: ='Carnes y Pescados'!A31 -> 0 | B31: ='Carnes y Pescados'!B31 -> Salmón | C31: ='Carnes y Pescados'!$A31*'Carnes y Pescados'!C31/100 -> 0 | D31: ='Carnes y Pescados'!$A31*'Carnes y Pescados'!D31/100 -> 0 | E31: ='Carnes y Pescados'!$A31*'Carnes y Pescados'!E31/100 -> 0 | F31: ='Carnes y Pescados'!$A31*'Carnes y Pescados'!F31/100 -> 0 | G31: ='Carnes y Pescados'!$A31*'Carnes y Pescados'!G31/100 -> 0 | H31: ='Carnes y Pescados'!$A31*'Carnes y Pescados'!H31/100 -> 0 | I31: ='Carnes y Pescados'!$A31*'Carnes y Pescados'!I31/100 -> 0 | J31: ='Carnes y Pescados'!$A31*'Carnes y Pescados'!J31/100 -> 0 | ... U31: ='Carnes y Pescados'!$A31*'Carnes y Pescados'!U31/100 -> 0
A32: ='Huevos y Lacteos'!A4 -> 90 | B32: ='Huevos y Lacteos'!B4 -> Huevo Entero | C32: ='Huevos y Lacteos'!$A4*'Huevos y Lacteos'!C4/100 -> 67.5 | D32: ='Huevos y Lacteos'!$A4*'Huevos y Lacteos'!D4/100 -> 145.8 | E32: ='Huevos y Lacteos'!$A4*'Huevos y Lacteos'!E4/100 -> 11.43 | F32: ='Huevos y Lacteos'!$A4*'Huevos y Lacteos'!F4/100 -> 10.89 | G32: ='Huevos y Lacteos'!$A4*'Huevos y Lacteos'!G4/100 -> 0.63 | H32: ='Huevos y Lacteos'!$A4*'Huevos y Lacteos'!H4/100 -> 117 | I32: ='Huevos y Lacteos'!$A4*'Huevos y Lacteos'!I4/100 -> 117 | J32: ='Huevos y Lacteos'!$A4*'Huevos y Lacteos'!J4/100 -> 180 | ... U32: ='Huevos y Lacteos'!$A4*'Huevos y Lacteos'!U4/100 -> 10.8
A33: ='Huevos y Lacteos'!A5 -> 300 | B33: ='Huevos y Lacteos'!B5 -> Huevo Clara | C33: ='Huevos y Lacteos'!$A5*'Huevos y Lacteos'!C5/100 -> 263.7 | D33: ='Huevos y Lacteos'!$A5*'Huevos y Lacteos'!D5/100 -> 138 | E33: ='Huevos y Lacteos'!$A5*'Huevos y Lacteos'!E5/100 -> 30.9 | F33: ='Huevos y Lacteos'!$A5*'Huevos y Lacteos'!F5/100 -> 0.3 | G33: ='Huevos y Lacteos'!$A5*'Huevos y Lacteos'!G5/100 -> 2.7 | H33: ='Huevos y Lacteos'!$A5*'Huevos y Lacteos'!H5/100 -> 450 | I33: ='Huevos y Lacteos'!$A5*'Huevos y Lacteos'!I5/100 -> 420 | J33: ='Huevos y Lacteos'!$A5*'Huevos y Lacteos'!J5/100 -> 54 | ... U33: ='Huevos y Lacteos'!$A5*'Huevos y Lacteos'!U5/100 -> 30
A34: ='Huevos y Lacteos'!A6 -> 0 | B34: ='Huevos y Lacteos'!B6 -> Huevo Yema | C34: ='Huevos y Lacteos'!$A6*'Huevos y Lacteos'!C6/100 -> 0 | D34: ='Huevos y Lacteos'!$A6*'Huevos y Lacteos'!D6/100 -> 0 | E34: ='Huevos y Lacteos'!$A6*'Huevos y Lacteos'!E6/100 -> 0 | F34: ='Huevos y Lacteos'!$A6*'Huevos y Lacteos'!F6/100 -> 0 | G34: ='Huevos y Lacteos'!$A6*'Huevos y Lacteos'!G6/100 -> 0 | H34: ='Huevos y Lacteos'!$A6*'Huevos y Lacteos'!H6/100 -> 0 | I34: ='Huevos y Lacteos'!$A6*'Huevos y Lacteos'!I6/100 -> 0 | J34: ='Huevos y Lacteos'!$A6*'Huevos y Lacteos'!J6/100 -> 0 | ... U34: ='Huevos y Lacteos'!$A6*'Huevos y Lacteos'!U6/100 -> 0
A35: ='Huevos y Lacteos'!A7 -> 0 | B35: ='Huevos y Lacteos'!B7 -> Flan de huevo | C35: ='Huevos y Lacteos'!$A7*'Huevos y Lacteos'!C7/100 -> 0 | D35: ='Huevos y Lacteos'!$A7*'Huevos y Lacteos'!D7/100 -> 0 | E35: ='Huevos y Lacteos'!$A7*'Huevos y Lacteos'!E7/100 -> 0 | F35: ='Huevos y Lacteos'!$A7*'Huevos y Lacteos'!F7/100 -> 0 | G35: ='Huevos y Lacteos'!$A7*'Huevos y Lacteos'!G7/100 -> 0 | H35: ='Huevos y Lacteos'!$A7*'Huevos y Lacteos'!H7/100 -> 0 | I35: ='Huevos y Lacteos'!$A7*'Huevos y Lacteos'!I7/100 -> 0 | J35: ='Huevos y Lacteos'!$A7*'Huevos y Lacteos'!J7/100 -> 0 | ... U35: ='Huevos y Lacteos'!$A7*'Huevos y Lacteos'!U7/100 -> 0
A37: ='Huevos y Lacteos'!A9 -> 0 | B37: ='Huevos y Lacteos'!B9 -> Suplementos Deportivos | C37: ='Huevos y Lacteos'!$A9*'Huevos y Lacteos'!C9/100 -> 0 | D37: ='Huevos y Lacteos'!$A9*'Huevos y Lacteos'!D9/100 -> 0 | E37: ='Huevos y Lacteos'!$A9*'Huevos y Lacteos'!E9/100 -> 0 | F37: ='Huevos y Lacteos'!$A9*'Huevos y Lacteos'!F9/100 -> 0 | G37: ='Huevos y Lacteos'!$A9*'Huevos y Lacteos'!G9/100 -> 0 | H37: ='Huevos y Lacteos'!$A9*'Huevos y Lacteos'!H9/100 -> 0 | I37: ='Huevos y Lacteos'!$A9*'Huevos y Lacteos'!I9/100 -> 0 | J37: ='Huevos y Lacteos'!$A9*'Huevos y Lacteos'!J9/100 -> 0 | ... U37: ='Huevos y Lacteos'!$A9*'Huevos y Lacteos'!U9/100 -> 0
A38: ='Huevos y Lacteos'!A10 -> 0 | B38: ='Huevos y Lacteos'!B10 -> Proteina de Suero (Concentrado) | C38: ='Huevos y Lacteos'!$A10*'Huevos y Lacteos'!C10/100 -> 0 | D38: ='Huevos y Lacteos'!$A10*'Huevos y Lacteos'!D10/100 -> 0 | E38: ='Huevos y Lacteos'!$A10*'Huevos y Lacteos'!E10/100 -> 0 | F38: ='Huevos y Lacteos'!$A10*'Huevos y Lacteos'!F10/100 -> 0 | G38: ='Huevos y Lacteos'!$A10*'Huevos y Lacteos'!G10/100 -> 0 | H38: ='Huevos y Lacteos'!$A10*'Huevos y Lacteos'!H10/100 -> 0 | I38: ='Huevos y Lacteos'!$A10*'Huevos y Lacteos'!I10/100 -> 0 | J38: ='Huevos y Lacteos'!$A10*'Huevos y Lacteos'!J10/100 -> 0 | ... U38: ='Huevos y Lacteos'!$A10*'Huevos y Lacteos'!U10/100 -> 0
A39: ='Huevos y Lacteos'!A11 -> 0 | B39: ='Huevos y Lacteos'!B11 -> Carbohidratos en Polvo | C39: ='Huevos y Lacteos'!$A11*'Huevos y Lacteos'!C11/100 -> 0 | D39: ='Huevos y Lacteos'!$A11*'Huevos y Lacteos'!D11/100 -> 0 | E39: ='Huevos y Lacteos'!$A11*'Huevos y Lacteos'!E11/100 -> 0 | F39: ='Huevos y Lacteos'!$A11*'Huevos y Lacteos'!F11/100 -> 0 | G39: ='Huevos y Lacteos'!$A11*'Huevos y Lacteos'!G11/100 -> 0 | H39: ='Huevos y Lacteos'!$A11*'Huevos y Lacteos'!H11/100 -> 0 | I39: ='Huevos y Lacteos'!$A11*'Huevos y Lacteos'!I11/100 -> 0 | J39: ='Huevos y Lacteos'!$A11*'Huevos y Lacteos'!J11/100 -> 0 | ... U39: ='Huevos y Lacteos'!$A11*'Huevos y Lacteos'!U11/100 -> 0
A40: ='Huevos y Lacteos'!A12 -> 35 | B40: ='Huevos y Lacteos'!B12 -> Proteina de Suero (Aislado ) | C40: ='Huevos y Lacteos'!$A12*'Huevos y Lacteos'!C12/100 -> 2.8 | D40: ='Huevos y Lacteos'!$A12*'Huevos y Lacteos'!D12/100 -> 129.36 | E40: ='Huevos y Lacteos'!$A12*'Huevos y Lacteos'!E12/100 -> 30.975 | F40: ='Huevos y Lacteos'!$A12*'Huevos y Lacteos'!F12/100 -> 0.63 | G40: ='Huevos y Lacteos'!$A12*'Huevos y Lacteos'!G12/100 -> 0.595 | H40: ='Huevos y Lacteos'!$A12*'Huevos y Lacteos'!H12/100 -> 106.575 | I40: ='Huevos y Lacteos'!$A12*'Huevos y Lacteos'!I12/100 -> 0 | J40: ='Huevos y Lacteos'!$A12*'Huevos y Lacteos'!J12/100 -> 0 | ... U40: ='Huevos y Lacteos'!$A12*'Huevos y Lacteos'!U12/100 -> 0
A41: ='Huevos y Lacteos'!A13 -> 0 | B41: ='Huevos y Lacteos'!B13 -> Ganador de Peso Gainer (60HC/30Prot) | C41: ='Huevos y Lacteos'!$A13*'Huevos y Lacteos'!C13/100 -> 0 | D41: ='Huevos y Lacteos'!$A13*'Huevos y Lacteos'!D13/100 -> 0 | E41: ='Huevos y Lacteos'!$A13*'Huevos y Lacteos'!E13/100 -> 0 | F41: ='Huevos y Lacteos'!$A13*'Huevos y Lacteos'!F13/100 -> 0 | G41: ='Huevos y Lacteos'!$A13*'Huevos y Lacteos'!G13/100 -> 0 | H41: ='Huevos y Lacteos'!$A13*'Huevos y Lacteos'!H13/100 -> 0 | I41: ='Huevos y Lacteos'!$A13*'Huevos y Lacteos'!I13/100 -> 0 | J41: ='Huevos y Lacteos'!$A13*'Huevos y Lacteos'!J13/100 -> 0 | ... U41: ='Huevos y Lacteos'!$A13*'Huevos y Lacteos'!U13/100 -> 0
A42: ='Huevos y Lacteos'!A14 -> 0 | B42: ='Huevos y Lacteos'!B14 -> 0 | C42: ='Huevos y Lacteos'!$A14*'Huevos y Lacteos'!C14/100 -> 0 | D42: ='Huevos y Lacteos'!$A14*'Huevos y Lacteos'!D14/100 -> 0 | E42: ='Huevos y Lacteos'!$A14*'Huevos y Lacteos'!E14/100 -> 0 | F42: ='Huevos y Lacteos'!$A14*'Huevos y Lacteos'!F14/100 -> 0 | G42: ='Huevos y Lacteos'!$A14*'Huevos y Lacteos'!G14/100 -> 0 | H42: ='Huevos y Lacteos'!$A14*'Huevos y Lacteos'!H14/100 -> 0 | I42: ='Huevos y Lacteos'!$A14*'Huevos y Lacteos'!I14/100 -> 0 | J42: ='Huevos y Lacteos'!$A14*'Huevos y Lacteos'!J14/100 -> 0 | ... U42: ='Huevos y Lacteos'!$A14*'Huevos y Lacteos'!U14/100 -> 0
